<!-- 需求 设置机器人底盘 并添加摄像头 -->
<robot name="mycar">
    <!-- 添加一个尺寸极小的 link 再去关联初始 link 与 base_link 关节高度刚好和 base_link 下沉的高度一致(半个底盘高度)-->
    <link name="base_footprint">
        <visual>
            <geometry>
                <box size="0.001 0.001 0.001" />
            </geometry>
        </visual>
    </link>
    <!-- 底盘 link -->
    <link name="base_link">
        <visual>
            <geometry>
                <box size="0.3 0.2 0.1" />
            </geometry>

            <!-- 偏移量与倾斜角度 -->
            <!-- 
                xyz 设置机器人模型分别在 x y z 上的偏移量

                rpy 用于设置倾斜弧度 x(翻滚) y(俯仰) z(偏航)
             -->
            <origin xyz="0 0 0 " rpy="0 0 0"/>

            <!-- 颜色 -->
            <material name="car_color">
                <color rgba="0.8 0.5 0 0.5" />
            </material>
        </visual>
    </link>
    <!-- 摄像头 link -->        
    <link name="camera">
        <visual>
            <geometry>
                <box size="0.02 0.05 0.05" />
            </geometry>

            <!-- 先使用默认(后期需要修改) -->
            <origin xyz="0 0 0.025 " rpy="0 0 0"/>

            <!-- 颜色 -->
            <material name="camera_color">
                <color rgba="0.0 0.0 1 0.5" />
            </material>
        </visual>
    </link>
    <!-- 关联 base_footprint 与 base_link -->
    <joint name="link_to_footprint" type="fixed">
        <!-- 父级 link -->
        <parent link="base_footprint" />
        <!-- 子级 link -->
        <child link="base_link" />
        <!-- 设置偏移量 -->
        <origin xyz="0 0 0.05" rpy="0 0 0" />
    </joint>

    <!-- 关节 -->
    <joint name="camera_to_base" type="continuous">
        <!-- 父级 link -->
        <parent link="base_link" />
        <!-- 子级 link -->
        <child link="camera" />
        <!-- 设置偏移量 -->
        <origin xyz="0.12 0 0.05" rpy="0 0 0" />
        <!-- 设置关节旋转参考的坐标轴 -->
        <axis xyz="0 0 1" />
    </joint>
</robot>